Workbook

Sheet Form Responses 1
A1: Dấu thời gian | B1: Zone của bạn (ghi đúng mẫu: Zone 1) | C1: Tên nhóm của bạn - ghi đúng mẫu: Nhóm 1 hoặc E1 (nếu trên bàn có ghi kí hiệu E1) | D1: Tên nhóm của nhóm được chấm - ghi đúng mẫu: Nhóm 1 hoặc E1 (nếu trên bàn có ghi kí hiệu E1) | E1: Tên dự án/chủ đề của nhóm được chấm | F1: Điểm bài toán và bối cảnh enterprise (Use case rõ, user rõ, dữ liệu và ràng buộc enterprise được mô tả hợp lý) | G1: Điểm kiến trúc triển khai (Chọn Cloud/On-prem/Hybrid có logic, giải thích được trade-off, phù hợp bối cảnh) | H1: Điểm Cost analysis (Bóc cost theo thành phần, có mức MVP và Growth, nhận diện hidden cost) | I1: Điểm Cost optimization (Chiến lược phù hợp, có lý do rõ, cân nhắc trade-off quality/cost) | J1: Điểm Reliability & Scaling (Có failure scenarios, fallback, monitoring, suy nghĩ về tải và độ ổn định) | K1: Điểm Định hướng Track Phase 2 (Chọn track có căn cứ, liên hệ với kỹ năng và nhu cầu dự án) | L1: Điểm Trình bày và phản biện (Trình bày rõ, đúng thời gian, trả lời câu hỏi có logic) | M1: 1 điểm mạnh nhất của đội (Viết ít nhất 1 câu cụ thể, nêu rõ phần nào ấn tượng nhất) | N1: 1 điểm cần cải thiện nhất Nêu rõ phần nào (deployment / cost / reliability / track) và lý do | O1: Câu hỏi hoặc phản biện dành cho đội Phải liên quan đến logic triển khai, cost hoặc reliability — không hỏi lại thông tin đã có trên slide | P1: Đề xuất nếu đội tiếp tục sang Phase 2 | Q1: Trao badge cho đội này | R1: Tong_diem | S1: Ten_nhom_duoc_cham_chuan | T1: Ten_nhom_cham_chuan | U1: Zone_chuan
A2: 46134.667 | B2: Zone 3 | C2: Nhóm 18 | D2: Nhóm 17 | E2: Manufacturing maintenance copilot | F2: 15 | G2: 20 | H2: 20 | I2: 15 | J2: 10 | L2: 5 | M2: Kĩ thuật tốt , tối ưu chi phí | N2: Triển khai thực tế còn khó khăn | O2: Cấu hình on-prem của nhóm là gì! | Q2: Best Cost Thinking | R2: =IF(A2="","",F2+G2+H2+I2+J2+L2) -> 85 | S2: =IFERROR(__xludf.dummyfunction("ARRAYFORMULA(IF(D2:D263="""", """", IFERROR(""NHÓM "" & MOD(VALUE(REGEXEXTRACT(D2:D263 & """", ""[0-9]+"")) - 1, 6) + 1, D2:D263)))"),"NHÓM 5") -> NHÓM 5 | T2: =IFERROR(__xludf.dummyfunction("ARRAYFORMULA(IF(C2:C263="""", """", IFERROR(""NHÓM "" & MOD(VALUE(REGEXEXTRACT(C2:C263 & """", ""[0-9]+"")) - 1, 6) + 1, C2:C263)))"),"NHÓM 6") -> NHÓM 6 | U2: =IFERROR(__xludf.dummyfunction("IF(B2="""","""",""Zone ""&IFERROR(VALUE(REGEXEXTRACT(TRIM(B2),""\d+"")),REGEXEXTRACT(TRIM(B2),""\d+"")))"),"Zone 3") -> Zone 3
A3: 46134.671 | B3: 3 | C3: 17 | D3: 18 | E3: Trợ lý y tế AI | F3: 15 | G3: 16 | H3: 16 | I3: 15 | J3: 10 | L3: 4 | M3: Trình bày nhanh gọn đầy đủ, giả định thực tế | N3: Cost to quá | O3: Giải quyết khoảng trống enterprise cụ thể ntn | R3: =IF(A3="","",F3+G3+H3+I3+J3+L3) -> 76 | S3: =IFERROR(__xludf.dummyfunction("""COMPUTED_VALUE"""),"NHÓM 6") -> NHÓM 6 | T3: =IFERROR(__xludf.dummyfunction("""COMPUTED_VALUE"""),"NHÓM 5") -> NHÓM 5 | U3: =IFERROR(__xludf.dummyfunction("IF(B3="""","""",""Zone ""&IFERROR(VALUE(REGEXEXTRACT(TRIM(B3),""\d+"")),REGEXEXTRACT(TRIM(B3),""\d+"")))"),"Zone 3") -> Zone 3
A4: 46134.671 | B4: Zone 4 | C4: Nhóm 22 | D4: Nhóm 34 | E4: Bank operation Copilot | F4: 15 | G4: 20 | H4: 20 | I4: 15 | J4: 10 | L4: 5 | M4: Xứ lý request khách hàng tốt | N4: Không | O4: Bên nhóm tính scale to hơn như nào | Q4: Best Enterprise Logic, Best Cost Thinking, Best Reliability Mindset, Best Track Recommendation, Best Critical Feedback | R4: =IF(A4="","",F4+G4+H4+I4+J4+L4) -> 85 | S4: =IFERROR(__xludf.dummyfunction("""COMPUTED_VALUE"""),"NHÓM 4") -> NHÓM 4 | T4: =IFERROR(__xludf.dummyfunction("""COMPUTED_VALUE"""),"NHÓM 4") -> NHÓM 4 | U4: =IFERROR(__xludf.dummyfunction("IF(B4="""","""",""Zone ""&IFERROR(VALUE(REGEXEXTRACT(TRIM(B4),""\d+"")),REGEXEXTRACT(TRIM(B4),""\d+"")))"),"Zone 4") -> Zone 4
A5: 46134.671 | B5: 4 | C5: Nhóm 34 | D5: Nhóm 22 | E5: University Admission & Students support Agent | F5: 15 | G5: 20 | H5: 20 | I5: 15 | J5: 10 | L5: 5 | M5: Tối ưu chi phí tốt | N5: Không | O5: Scale dự án như thế nào ? | Q5: Best Enterprise Logic, Best Cost Thinking, Best Reliability Mindset, Best Track Recommendation, Best Critical Feedback | R5: =IF(A5="","",F5+G5+H5+I5+J5+L5) -> 85 | S5: =IFERROR(__xludf.dummyfunction("""COMPUTED_VALUE"""),"NHÓM 4") -> NHÓM 4 | T5: =IFERROR(__xludf.dummyfunction("""COMPUTED_VALUE"""),"NHÓM 4") -> NHÓM 4 | U5: =IFERROR(__xludf.dummyfunction("IF(B5="""","""",""Zone ""&IFERROR(VALUE(REGEXEXTRACT(TRIM(B5),""\d+"")),REGEXEXTRACT(TRIM(B5),""\d+"")))"),"Zone 4") -> Zone 4
A6: 46134.674 | B6: Zone 4 | C6: Nhóm 21 | D6: Nhóm 20 | E6: Trợ lí ảo xanh SM | F6: 15 | G6: 20 | H6: 20 | I6: 12 | J6: 10 | L6: 4 | M6: Có phân tích, benmark cụ thể và chiến lược phát triển | N6: Deployment:UI/UX còn hơi đơn giản | O6: Làm sao PII hoàn chỉnh khi nộp form đăng kí tài xé | Q6: Best Enterprise Logic | R6: =IF(A6="","",F6+G6+H6+I6+J6+L6) -> 81 | S6: =IFERROR(__xludf.dummyfunction("""COMPUTED_VALUE"""),"NHÓM 2") -> NHÓM 2 | T6: =IFERROR(__xludf.dummyfunction("""COMPUTED_VALUE"""),"NHÓM 3") -> NHÓM 3 | U6: =IFERROR(__xludf.dummyfunction("IF(B6="""","""",""Zone ""&IFERROR(VALUE(REGEXEXTRACT(TRIM(B6),""\d+"")),REGEXEXTRACT(TRIM(B6),""\d+"")))"),"Zone 4") -> Zone 4
A7: 46134.674 | B7: Zone 4 | C7: Nhóm 19 | D7: Nhóm 22 | E7: Agent hỗ trợ hỏi đáp sinh viên | F7: 15 | G7: 16 | H7: 16 | I7: 15 | J7: 8 | L7: 4 | M7: Thuyết trình mạch lạc | N7: Phần cost cần cải thiện vì dùng hybrid nhưng chưa rõ chi phí hạ tầng | O7: Giả sử agent trả sai thông tin của trường thì phải làm như nào | Q7: Best Enterprise Logic | R7: =IF(A7="","",F7+G7+H7+I7+J7+L7) -> 74 | S7: =IFERROR(__xludf.dummyfunction("""COMPUTED_VALUE"""),"NHÓM 4") -> NHÓM 4 | T7: =IFERROR(__xludf.dummyfunction("""COMPUTED_VALUE"""),"NHÓM 1") -> NHÓM 1 | U7: =IFERROR(__xludf.dummyfunction("IF(B7="""","""",""Zone ""&IFERROR(VALUE(REGEXEXTRACT(TRIM(B7),""\d+"")),REGEXEXTRACT(TRIM(B7),""\d+"")))"),"Zone 4") -> Zone 4
A8: 46134.674 | B8: Zone 4 | C8: Nhóm 19 | D8: Nhóm 22 | E8: Agent hỗ trợ hỏi đáp sinh viên | F8: 15 | G8: 16 | H8: 16 | I8: 15 | J8: 8 | L8: 4 | M8: Thuyết trình mạch lạc | N8: Phần cost cần cải thiện vì dùng hybrid nhưng chưa rõ chi phí hạ tầng | O8: Giả sử agent trả sai thông tin của trường thì phải làm như nào | Q8: Best Enterprise Logic | R8: =IF(A8="","",F8+G8+H8+I8+J8+L8) -> 74 | S8: =IFERROR(__xludf.dummyfunction("""COMPUTED_VALUE"""),"NHÓM 4") -> NHÓM 4 | T8: =IFERROR(__xludf.dummyfunction("""COMPUTED_VALUE"""),"NHÓM 1") -> NHÓM 1 | U8: =IFERROR(__xludf.dummyfunction("IF(B8="""","""",""Zone ""&IFERROR(VALUE(REGEXEXTRACT(TRIM(B8),""\d+"")),REGEXEXTRACT(TRIM(B8),""\d+"")))"),"Zone 4") -> Zone 4
A9: 46134.675 | B9: Zone 4 | C9: Nhóm 20 | D9: Nhóm 34 | E9: Bank Operations Copilot | F9: 15 | G9: 20 | H9: 12 | I9: 15 | J9: 8 | L9: 4 | M9: Phân tích kỹ về ngành ngân hàng, quy định của ngân hàng (hiểu domain knowledge) để xây được chatbot đi đúng hướng | N9: Phần cost analysis nhóm chưa chia rõ ràng lắm, mới chỉ specify là cho 10000 user, setup ban đầu 200 triệu, chưa rõ 200 triệu là chi tiết các thành phần nào | O9: Nhờ nhóm giải đáp thêm về cấu trúc chi phí cho giai đoạn set up MVP, chi phí 200 triệu có vẻ hơi thấp, chưa đủ trả lương cho nhân sự làm dự án | Q9: Best Enterprise Logic | R9: =IF(A9="","",F9+G9+H9+I9+J9+L9) -> 74 | S9: =IFERROR(__xludf.dummyfunction("""COMPUTED_VALUE"""),"NHÓM 4") -> NHÓM 4 | T9: =IFERROR(__xludf.dummyfunction("""COMPUTED_VALUE"""),"NHÓM 2") -> NHÓM 2 | U9: =IFERROR(__xludf.dummyfunction("IF(B9="""","""",""Zone ""&IFERROR(VALUE(REGEXEXTRACT(TRIM(B9),""\d+"")),REGEXEXTRACT(TRIM(B9),""\d+"")))"),"Zone 4") -> Zone 4
A10: 46134.675 | B10: Zone 4 | C10: Nhóm 22 | D10: Nhóm 20 | E10: Trợ lý ảo Xanh SM | F10: 15 | G10: 20 | H10: 20 | I10: 15 | J10: 10 | L10: 5 | M10: Thiết kế hệ thống tối ưu cost tốt | N10: Tính năng cancel quy trình điền form lúc bấm nhầm | O10: Nhóm tính scale dự án như nào | Q10: Best Enterprise Logic, Best Cost Thinking, Best Reliability Mindset, Best Track Recommendation, Best Critical Feedback | R10: =IF(A10="","",F10+G10+H10+I10+J10+L10) -> 85 | S10: =IFERROR(__xludf.dummyfunction("""COMPUTED_VALUE"""),"NHÓM 2") -> NHÓM 2 | T10: =IFERROR(__xludf.dummyfunction("""COMPUTED_VALUE"""),"NHÓM 4") -> NHÓM 4 | U10: =IFERROR(__xludf.dummyfunction("IF(B10="""","""",""Zone ""&IFERROR(VALUE(REGEXEXTRACT(TRIM(B10),""\d+"")),REGEXEXTRACT(TRIM(B10),""\d+"")))"),"Zone 4") -> Zone 4
A11: 46134.675 | B11: 4 | C11: 34 | D11: 19 | E11: Vinschool one | F11: 12 | G11: 12 | H11: 8 | I11: 6 | J11: 8 | L11: 5 | M11: Có demo luôn, hệ thống rõ luồng, giải quyết đúng bài toán | N11: Hệ thống hoạt động sai về logic tối ưu chi phí: nên tìm giải pháp ít chi phí nhất thay vì gọi llm mạnh từ đầu | O11: Tại sao không cho rulebase trước khi gọi llm? Chi phí ước tính cụ thể bao nhiêu? | R11: =IF(A11="","",F11+G11+H11+I11+J11+L11) -> 51 | S11: =IFERROR(__xludf.dummyfunction("""COMPUTED_VALUE"""),"NHÓM 1") -> NHÓM 1 | T11: =IFERROR(__xludf.dummyfunction("""COMPUTED_VALUE"""),"NHÓM 4") -> NHÓM 4 | U11: =IFERROR(__xludf.dummyfunction("IF(B11="""","""",""Zone ""&IFERROR(VALUE(REGEXEXTRACT(TRIM(B11),""\d+"")),REGEXEXTRACT(TRIM(B11),""\d+"")))"),"Zone 4") -> Zone 4
A12: 46134.676 | B12: 4 | C12: 21 | D12: 34 | E12: Bank Copilot Operation | F12: 15 | G12: 20 | H12: 20 | I12: 15 | J12: 10 | L12: 5 | M12: Tuân thủ rõ các điều luật của nhà nước về bảo mật thôgn tin | N12: tìm hiểu sâu hơn về MLops về vấn đề bảo trì và giám sát | O12: cách đề ẩn danh dữ liệu khác hàng như nào khi dùng AI | Q12: Best Reliability Mindset | R12: =IF(A12="","",F12+G12+H12+I12+J12+L12) -> 85 | S12: =IFERROR(__xludf.dummyfunction("""COMPUTED_VALUE"""),"NHÓM 4") -> NHÓM 4 | T12: =IFERROR(__xludf.dummyfunction("""COMPUTED_VALUE"""),"NHÓM 3") -> NHÓM 3 | U12: =IFERROR(__xludf.dummyfunction("IF(B12="""","""",""Zone ""&IFERROR(VALUE(REGEXEXTRACT(TRIM(B12),""\d+"")),REGEXEXTRACT(TRIM(B12),""\d+"")))"),"Zone 4") -> Zone 4
A13: 46134.676 | B13: Zone 3 | C13: Nhóm 1 | D13: Nhóm 2 | E13: VinUni Smart AI Assistant | F13: 12 | G13: 16 | H13: 16 | I13: 12 | J13: 8 | L13: 4 | M13: Mạnh đều | N13: Chưa tìm ra | O13: Ko có | R13: =IF(A13="","",F13+G13+H13+I13+J13+L13) -> 68 | S13: =IFERROR(__xludf.dummyfunction("""COMPUTED_VALUE"""),"NHÓM 2") -> NHÓM 2 | T13: =IFERROR(__xludf.dummyfunction("""COMPUTED_VALUE"""),"NHÓM 1") -> NHÓM 1 | U13: =IFERROR(__xludf.dummyfunction("IF(B13="""","""",""Zone ""&IFERROR(VALUE(REGEXEXTRACT(TRIM(B13),""\d+"")),REGEXEXTRACT(TRIM(B13),""\d+"")))"),"Zone 3") -> Zone 3
A14: 46134.677 | B14: 5 | C14: Nhóm 4 | D14: Nhóm 1 | E14: Trợ lý học tập đa phương thức | F14: 12 | G14: 12 | H14: 16 | I14: 9 | J14: 8 | L14: 3 | M14: Hybird deployment | N14: Chưa ứng dụng dc cho nhiều tệp khách hàng/ ngách nhỏ | O14: Hiện web bắt người dùng nhìn vào màn hình full time, chưa phù hợp khi họ viết bài, ngoảnh mặt đi nói chuyện,... | Q14: Best Enterprise Logic | R14: =IF(A14="","",F14+G14+H14+I14+J14+L14) -> 60 | S14: =IFERROR(__xludf.dummyfunction("""COMPUTED_VALUE"""),"NHÓM 1") -> NHÓM 1 | T14: =IFERROR(__xludf.dummyfunction("""COMPUTED_VALUE"""),"NHÓM 4") -> NHÓM 4 | U14: =IFERROR(__xludf.dummyfunction("IF(B14="""","""",""Zone ""&IFERROR(VALUE(REGEXEXTRACT(TRIM(B14),""\d+"")),REGEXEXTRACT(TRIM(B14),""\d+"")))"),"Zone 5") -> Zone 5
A15: 46134.677 | B15: 5 | C15: 2 | D15: 1 | E15: Trợ lý học tập đa phương thức | F15: 12 | G15: 16 | H15: 16 | I15: 12 | J15: 8 | L15: 4 | M15: Có kiến thức cụ thể, nắm bắt được usecase | N15: Chi phí vẫn ở mức ổn với MVP chưa tốt cho production | O15: Trường hợp use vẫn dùng màn hình nhưng bật sang tab ytb hoặc fb thì sẽ như nào | Q15: Best Reliability Mindset | R15: =IF(A15="","",F15+G15+H15+I15+J15+L15) -> 68 | S15: =IFERROR(__xludf.dummyfunction("""COMPUTED_VALUE"""),"NHÓM 1") -> NHÓM 1 | T15: =IFERROR(__xludf.dummyfunction("""COMPUTED_VALUE"""),"NHÓM 2") -> NHÓM 2 | U15: =IFERROR(__xludf.dummyfunction("IF(B15="""","""",""Zone ""&IFERROR(VALUE(REGEXEXTRACT(TRIM(B15),""\d+"")),REGEXEXTRACT(TRIM(B15),""\d+"")))"),"Zone 5") -> Zone 5
A16: 46134.677 | B16: 3 | C16: 18 | D16: 14 | E16: Vinuni smart AI Assistant | F16: 12 | G16: 16 | H16: 16 | I16: 15 | J16: 8 | L16: 4 | M16: Cost optimization tốt. | N16: Phần estimate lượng users chưa hợp lý. | O16: Dữ liệu nhạy cảm của user là gì? | R16: =IF(A16="","",F16+G16+H16+I16+J16+L16) -> 71 | S16: =IFERROR(__xludf.dummyfunction("""COMPUTED_VALUE"""),"NHÓM 2") -> NHÓM 2 | T16: =IFERROR(__xludf.dummyfunction("""COMPUTED_VALUE"""),"NHÓM 6") -> NHÓM 6 | U16: =IFERROR(__xludf.dummyfunction("IF(B16="""","""",""Zone ""&IFERROR(VALUE(REGEXEXTRACT(TRIM(B16),""\d+"")),REGEXEXTRACT(TRIM(B16),""\d+"")))"),"Zone 3") -> Zone 3
A17: 46134.677 | B17: 4 | C17: 23 | D17: 22 | E17: Agent hỗ trợ hỏi đáp về tuyển sinh cho sinh viên | F17: 15 | G17: 16 | H17: 20 | I17: 12 | J17: 6 | L17: 4 | M17: User rõ, use case rõ, dữ liệu và ràng buộc hợp lý | N17: Phần monitoring chưa rõ ràng, phản biện hơi chung chung | O17: Đối với các trường hợp mà agent trả lời sang thông tin như học phí thì chiến lược của team cụ thể như thế nào | R17: =IF(A17="","",F17+G17+H17+I17+J17+L17) -> 73 | S17: =IFERROR(__xludf.dummyfunction("""COMPUTED_VALUE"""),"NHÓM 4") -> NHÓM 4 | T17: =IFERROR(__xludf.dummyfunction("""COMPUTED_VALUE"""),"NHÓM 5") -> NHÓM 5 | U17: =IFERROR(__xludf.dummyfunction("IF(B17="""","""",""Zone ""&IFERROR(VALUE(REGEXEXTRACT(TRIM(B17),""\d+"")),REGEXEXTRACT(TRIM(B17),""\d+"")))"),"Zone 4") -> Zone 4
A18: 46134.678 | B18: 5 | C18: 29 | D18: E1 | E18: Trợ lý học tập đa phương thức | F18: 9 | G18: 12 | H18: 12 | I18: 12 | J18: 6 | L18: 4 | M18: Ý tưởng triển khai tốt | N18: Không | O18: Không vì luồn ý tưởng tốt | Q18: Best Reliability Mindset | R18: =IF(A18="","",F18+G18+H18+I18+J18+L18) -> 55 | S18: =IFERROR(__xludf.dummyfunction("""COMPUTED_VALUE"""),"NHÓM 1") -> NHÓM 1 | T18: =IFERROR(__xludf.dummyfunction("""COMPUTED_VALUE"""),"NHÓM 5") -> NHÓM 5 | U18: =IFERROR(__xludf.dummyfunction("IF(B18="""","""",""Zone ""&IFERROR(VALUE(REGEXEXTRACT(TRIM(B18),""\d+"")),REGEXEXTRACT(TRIM(B18),""\d+"")))"),"Zone 5") -> Zone 5
A19: 46134.678 | B19: 6 | C19: Nhóm 31 | D19: Nhóm 33 | E19: XanhSm ai help center | F19: 9 | G19: 4 | H19: 20 | I19: 9 | J19: 8 | L19: 4 | M19: Slide rõ ràng, số liệu có nguồn rõ ràng | N19: Nên thêm demo app nếu có | O19: Nhóm chỉ đưa ra số liệu cho các case chat giữa người dùng và tài xế nhưng phần lớn các cuốc xe không có lịch sử chat hoặc chỉ có cuộc gọi | Q19: Best Cost Thinking | R19: =IF(A19="","",F19+G19+H19+I19+J19+L19) -> 54 | S19: =IFERROR(__xludf.dummyfunction("""COMPUTED_VALUE"""),"NHÓM 3") -> NHÓM 3 | T19: =IFERROR(__xludf.dummyfunction("""COMPUTED_VALUE"""),"NHÓM 1") -> NHÓM 1 | U19: =IFERROR(__xludf.dummyfunction("IF(B19="""","""",""Zone ""&IFERROR(VALUE(REGEXEXTRACT(TRIM(B19),""\d+"")),REGEXEXTRACT(TRIM(B19),""\d+"")))"),"Zone 6") -> Zone 6
A20: 46134.679 | B20: Zone 2 | C20: Nhóm 2 | D20: Nhóm 3 | E20: EduPlusAI | F20: 9 | G20: 12 | H20: 16 | I20: 9 | J20: 4 | L20: 3 | M20: Có cost analysis cụ thể | N20: còn thiếu monitoring | O20: không có | Q20: Best Reliability Mindset | R20: =IF(A20="","",F20+G20+H20+I20+J20+L20) -> 53 | S20: =IFERROR(__xludf.dummyfunction("""COMPUTED_VALUE"""),"NHÓM 3") -> NHÓM 3 | T20: =IFERROR(__xludf.dummyfunction("""COMPUTED_VALUE"""),"NHÓM 2") -> NHÓM 2 | U20: =IFERROR(__xludf.dummyfunction("IF(B20="""","""",""Zone ""&IFERROR(VALUE(REGEXEXTRACT(TRIM(B20),""\d+"")),REGEXEXTRACT(TRIM(B20),""\d+"")))"),"Zone 2") -> Zone 2
A21: 46134.679 | B21: Zone 2 | C21: Nhóm 12 | D21: Nhóm 9 | E21: EduPlusAI | F21: 12 | G21: 16 | H21: 12 | I21: 15 | J21: 8 | L21: 5 | M21: Trình bày rõ ràng, | N21: Cost chưa làm rõ ở cập nhật database | O21: Tại sao ko tự huấn luyện llm riêng để trả lời | Q21: Best Critical Feedback | R21: =IF(A21="","",F21+G21+H21+I21+J21+L21) -> 68 | S21: =IFERROR(__xludf.dummyfunction("""COMPUTED_VALUE"""),"NHÓM 3") -> NHÓM 3 | T21: =IFERROR(__xludf.dummyfunction("""COMPUTED_VALUE"""),"NHÓM 6") -> NHÓM 6 | U21: =IFERROR(__xludf.dummyfunction("IF(B21="""","""",""Zone ""&IFERROR(VALUE(REGEXEXTRACT(TRIM(B21),""\d+"")),REGEXEXTRACT(TRIM(B21),""\d+"")))"),"Zone 2") -> Zone 2
A22: 46134.679 | B22: Zone 4 | C22: Nhóm 21 | D22: Nhóm 22 | E22: University admissions and student support agent | F22: 15 | G22: 20 | H22: 20 | I22: 15 | J22: 10 | L22: 5 | M22: Tối ưu chi phí tốt | N22: Cơ chế model cần tối ưu hơn (latency cao) | O22: Làm sao đảm bảo thông tin của nhà trường | Q22: Best Track Recommendation, Best Critical Feedback | R22: =IF(A22="","",F22+G22+H22+I22+J22+L22) -> 85 | S22: =IFERROR(__xludf.dummyfunction("""COMPUTED_VALUE"""),"NHÓM 4") -> NHÓM 4 | T22: =IFERROR(__xludf.dummyfunction("""COMPUTED_VALUE"""),"NHÓM 3") -> NHÓM 3 | U22: =IFERROR(__xludf.dummyfunction("IF(B22="""","""",""Zone ""&IFERROR(VALUE(REGEXEXTRACT(TRIM(B22),""\d+"")),REGEXEXTRACT(TRIM(B22),""\d+"")))"),"Zone 4") -> Zone 4
A23: 46134.679 | B23: Zone 3 | C23: Nhóm 1 | D23: Nhóm 2 | E23: Hệ thống trợ lý ảo thông minh | F23: 15 | G23: 20 | H23: 20 | I23: 15 | J23: 10 | L23: 5 | M23: Trình bày ấn tượng | N23: Tối ưu các chi phí deployment lên các nền tảng cloud | O23: Các cơ chế báo cáo lỗi hệ thống hoạt động như thế nào? | Q23: Best Enterprise Logic | R23: =IF(A23="","",F23+G23+H23+I23+J23+L23) -> 85 | S23: =IFERROR(__xludf.dummyfunction("""COMPUTED_VALUE"""),"NHÓM 2") -> NHÓM 2 | T23: =IFERROR(__xludf.dummyfunction("""COMPUTED_VALUE"""),"NHÓM 1") -> NHÓM 1 | U23: =IFERROR(__xludf.dummyfunction("IF(B23="""","""",""Zone ""&IFERROR(VALUE(REGEXEXTRACT(TRIM(B23),""\d+"")),REGEXEXTRACT(TRIM(B23),""\d+"")))"),"Zone 3") -> Zone 3
A24: 46134.679 | B24: Zone 6 | C24: Nhóm 32 | D24: Nhóm 33 | E24: XanhSM AI help center | F24: 15 | G24: 12 | H24: 16 | I24: 12 | J24: 8 | L24: 4 | M24: Work flow rõ ràng, giải thích dễ hiểu | N24: Chưa triển khai guardrail | O24: Vì sao không triển khai guardrail? | R24: =IF(A24="","",F24+G24+H24+I24+J24+L24) -> 67 | S24: =IFERROR(__xludf.dummyfunction("""COMPUTED_VALUE"""),"NHÓM 3") -> NHÓM 3 | T24: =IFERROR(__xludf.dummyfunction("""COMPUTED_VALUE"""),"NHÓM 2") -> NHÓM 2 | U24: =IFERROR(__xludf.dummyfunction("IF(B24="""","""",""Zone ""&IFERROR(VALUE(REGEXEXTRACT(TRIM(B24),""\d+"")),REGEXEXTRACT(TRIM(B24),""\d+"")))"),"Zone 6") -> Zone 6
A25: 46134.679 | B25: Zone 2 | C25: Nhóm 12 | D25: Nhóm 11 | E25: VinUni Admissions Agent | F25: 15 | G25: 20 | H25: 20 | I25: 15 | J25: 10 | L25: 5 | M25: Slide đẹp, trình bày rõ ràng, ý tưởng độc đáo | N25: Ko có gì | O25: Không có | Q25: Best Enterprise Logic, Best Cost Thinking, Best Reliability Mindset, Best Track Recommendation, Best Critical Feedback | R25: =IF(A25="","",F25+G25+H25+I25+J25+L25) -> 85 | S25: =IFERROR(__xludf.dummyfunction("""COMPUTED_VALUE"""),"NHÓM 5") -> NHÓM 5 | T25: =IFERROR(__xludf.dummyfunction("""COMPUTED_VALUE"""),"NHÓM 6") -> NHÓM 6 | U25: =IFERROR(__xludf.dummyfunction("IF(B25="""","""",""Zone ""&IFERROR(VALUE(REGEXEXTRACT(TRIM(B25),""\d+"")),REGEXEXTRACT(TRIM(B25),""\d+"")))"),"Zone 2") -> Zone 2
A26: 46134.68 | B26: Zone 4 | C26: Nhóm 22 | D26: Nhóm 21 | E26: Bank operation Copilot | F26: 15 | G26: 20 | H26: 20 | I26: 15 | J26: 10 | L26: 5 | M26: Các ràng buộc define rõ | N26: Nghiệp vụ ngân hàng cần rõ hơn | O26: Nhóm sẽ scale dự án như nào? | Q26: Best Enterprise Logic, Best Cost Thinking, Best Reliability Mindset, Best Track Recommendation, Best Critical Feedback | R26: =IF(A26="","",F26+G26+H26+I26+J26+L26) -> 85 | S26: =IFERROR(__xludf.dummyfunction("""COMPUTED_VALUE"""),"NHÓM 3") -> NHÓM 3 | T26: =IFERROR(__xludf.dummyfunction("""COMPUTED_VALUE"""),"NHÓM 4") -> NHÓM 4 | U26: =IFERROR(__xludf.dummyfunction("IF(B26="""","""",""Zone ""&IFERROR(VALUE(REGEXEXTRACT(TRIM(B26),""\d+"")),REGEXEXTRACT(TRIM(B26),""\d+"")))"),"Zone 4") -> Zone 4
A27: 46134.68 | B27: Zone 2 | C27: Nhóm 10 | D27: Nhóm 9 | E27: EduPlusAI | F27: 12 | G27: 16 | H27: 16 | I27: 12 | J27: 8 | L27: 5 | M27: Slide minh hoạt trực quan, nội dung rõ ràng | N27: Có thể sử dụng llm local cho câu hỏi định tuyến tiết kiệm chi phí | O27: Câu hỏi định tuyến có sẵn đơn giản tại sao không dùng rule-base mà phải sài GPT3-5. | R27: =IF(A27="","",F27+G27+H27+I27+J27+L27) -> 69 | S27: =IFERROR(__xludf.dummyfunction("""COMPUTED_VALUE"""),"NHÓM 3") -> NHÓM 3 | T27: =IFERROR(__xludf.dummyfunction("""COMPUTED_VALUE"""),"NHÓM 4") -> NHÓM 4 | U27: =IFERROR(__xludf.dummyfunction("IF(B27="""","""",""Zone ""&IFERROR(VALUE(REGEXEXTRACT(TRIM(B27),""\d+"")),REGEXEXTRACT(TRIM(B27),""\d+"")))"),"Zone 2") -> Zone 2
A28: 46134.68 | B28: Zone 3 | C28: Nhóm 4 | D28: Nhóm 2 | E28: VinUni Smart AI Assistant | F28: 12 | G28: 16 | H28: 16 | I28: 12 | J28: 8 | L28: 4 | M28: Slide sạch đẹp | N28: Deployment | O28: Dữ liệu lưu trữ 2 nơi là On-premise và cloud, thì nếu một câu hỏi cần 2 loại dữ liệu mà một bên gặp vấn đề thì như thế nào | R28: =IF(A28="","",F28+G28+H28+I28+J28+L28) -> 68 | S28: =IFERROR(__xludf.dummyfunction("""COMPUTED_VALUE"""),"NHÓM 2") -> NHÓM 2 | T28: =IFERROR(__xludf.dummyfunction("""COMPUTED_VALUE"""),"NHÓM 4") -> NHÓM 4 | U28: =IFERROR(__xludf.dummyfunction("IF(B28="""","""",""Zone ""&IFERROR(VALUE(REGEXEXTRACT(TRIM(B28),""\d+"")),REGEXEXTRACT(TRIM(B28),""\d+"")))"),"Zone 3") -> Zone 3
A29: 46134.68 | B29: Zone 4 | C29: Nhóm 19 | D29: Nhóm 23 | E29: Chatbot cho Vinfast | F29: 15 | G29: 20 | H29: 20 | I29: 12 | J29: 10 | L29: 5 | M29: Phản biện mạch lạc | N29: Cần cải thiện sự rõ ràng hơn về chi phí ước tính. Vì có 1 số nhập nhằng trong việc tính toán chi phí | O29: Làm thế nào để chứng minh được về sự cải thiện hallucination trong đề tài của các bạn | Q29: Best Enterprise Logic | R29: =IF(A29="","",F29+G29+H29+I29+J29+L29) -> 82 | S29: =IFERROR(__xludf.dummyfunction("""COMPUTED_VALUE"""),"NHÓM 5") -> NHÓM 5 | T29: =IFERROR(__xludf.dummyfunction("""COMPUTED_VALUE"""),"NHÓM 1") -> NHÓM 1 | U29: =IFERROR(__xludf.dummyfunction("IF(B29="""","""",""Zone ""&IFERROR(VALUE(REGEXEXTRACT(TRIM(B29),""\d+"")),REGEXEXTRACT(TRIM(B29),""\d+"")))"),"Zone 4") -> Zone 4
A30: 46134.68 | B30: Zone 4 | C30: Nhóm 19 | D30: Nhóm 23 | E30: Chatbot cho Vinfast | F30: 15 | G30: 20 | H30: 20 | I30: 12 | J30: 10 | L30: 5 | M30: Phản biện mạch lạc | N30: Cần cải thiện sự rõ ràng hơn về chi phí ước tính. Vì có 1 số nhập nhằng trong việc tính toán chi phí | O30: Làm thế nào để chứng minh được về sự cải thiện hallucination trong đề tài của các bạn | Q30: Best Enterprise Logic | R30: =IF(A30="","",F30+G30+H30+I30+J30+L30) -> 82 | S30: =IFERROR(__xludf.dummyfunction("""COMPUTED_VALUE"""),"NHÓM 5") -> NHÓM 5 | T30: =IFERROR(__xludf.dummyfunction("""COMPUTED_VALUE"""),"NHÓM 1") -> NHÓM 1 | U30: =IFERROR(__xludf.dummyfunction("IF(B30="""","""",""Zone ""&IFERROR(VALUE(REGEXEXTRACT(TRIM(B30),""\d+"")),REGEXEXTRACT(TRIM(B30),""\d+"")))"),"Zone 4") -> Zone 4
A31: 46134.68 | B31: 4 | C31: Nhóm 20 | D31: Nhóm 21 | E31: Bank operations copilot | F31: 12 | G31: 20 | H31: 20 | I31: 15 | J31: 10 | L31: 4 | M31: Team mạnh nhất ở phần reliability & scaling, đã cân nhắc nhiều trường hợp có thể xảy ra trong tương lai khi deploy thực tế cho user | N31: Tổng quan dự án team chưa nêu rõ lắm | O31: Nhờ team làm rõ hơn về nội dung nghiệp vụ cụ thể chatbot sẽ xử lý | Q31: Best Reliability Mindset | R31: =IF(A31="","",F31+G31+H31+I31+J31+L31) -> 81 | S31: =IFERROR(__xludf.dummyfunction("""COMPUTED_VALUE"""),"NHÓM 3") -> NHÓM 3 | T31: =IFERROR(__xludf.dummyfunction("""COMPUTED_VALUE"""),"NHÓM 2") -> NHÓM 2 | U31: =IFERROR(__xludf.dummyfunction("IF(B31="""","""",""Zone ""&IFERROR(VALUE(REGEXEXTRACT(TRIM(B31),""\d+"")),REGEXEXTRACT(TRIM(B31),""\d+"")))"),"Zone 4") -> Zone 4
A32: 46134.68 | B32: 3 | C32: Nhóm 17 | D32: 14 | E32: VinUni smart AI | F32: 12 | G32: 16 | H32: 16 | I32: 12 | J32: 8 | L32: 4 | M32: Trình bày tốt | N32: Reliability cần cả thiện | O32: Tính cost như vậy đã hợp lý? | Q32: Best Cost Thinking, Best Track Recommendation | R32: =IF(A32="","",F32+G32+H32+I32+J32+L32) -> 68 | S32: =IFERROR(__xludf.dummyfunction("""COMPUTED_VALUE"""),"NHÓM 2") -> NHÓM 2 | T32: =IFERROR(__xludf.dummyfunction("""COMPUTED_VALUE"""),"NHÓM 5") -> NHÓM 5 | U32: =IFERROR(__xludf.dummyfunction("IF(B32="""","""",""Zone ""&IFERROR(VALUE(REGEXEXTRACT(TRIM(B32),""\d+"")),REGEXEXTRACT(TRIM(B32),""\d+"")))"),"Zone 3") -> Zone 3
A33: 46134.68 | B33: 5 | C33: 26 | D33: 24 | E33: Trợ lý học tập đa phương thức | F33: 9 | G33: 16 | H33: 16 | I33: 12 | J33: 8 | L33: 4 | M33: Workflow chi tiết | N33: Chưa rõ độ tin cậy của model local | O33: Chi phí tối ưu nhưng liệu có đảm bảo khi sử dụng model local open source | R33: =IF(A33="","",F33+G33+H33+I33+J33+L33) -> 65 | S33: =IFERROR(__xludf.dummyfunction("""COMPUTED_VALUE"""),"NHÓM 6") -> NHÓM 6 | T33: =IFERROR(__xludf.dummyfunction("""COMPUTED_VALUE"""),"NHÓM 2") -> NHÓM 2 | U33: =IFERROR(__xludf.dummyfunction("IF(B33="""","""",""Zone ""&IFERROR(VALUE(REGEXEXTRACT(TRIM(B33),""\d+"")),REGEXEXTRACT(TRIM(B33),""\d+"")))"),"Zone 5") -> Zone 5
A34: 46134.681 | B34: Zone 2 | C34: Nhóm 1 | D34: Nhóm 3 | E34: EduPlusAI | F34: 12 | G34: 16 | H34: 16 | I34: 12 | J34: 8 | L34: 5 | M34: Trình bày rõ ràng | N34: Deploy | O34: Sao không fine tuning model để chạy local mà phải dùng cloud | Q34: Best Enterprise Logic, Best Cost Thinking, Best Reliability Mindset | R34: =IF(A34="","",F34+G34+H34+I34+J34+L34) -> 69 | S34: =IFERROR(__xludf.dummyfunction("""COMPUTED_VALUE"""),"NHÓM 3") -> NHÓM 3 | T34: =IFERROR(__xludf.dummyfunction("""COMPUTED_VALUE"""),"NHÓM 1") -> NHÓM 1 | U34: =IFERROR(__xludf.dummyfunction("IF(B34="""","""",""Zone ""&IFERROR(VALUE(REGEXEXTRACT(TRIM(B34),""\d+"")),REGEXEXTRACT(TRIM(B34),""\d+"")))"),"Zone 2") -> Zone 2
A35: 46134.681 | B35: 4 | C35: 23 | D35: 19 | E35: Ứng dụng AI quản lý học sinh vinschool | F35: 15 | G35: 20 | H35: 12 | I35: 12 | J35: 8 | L35: 4 | M35: Có giao diện demo rõ ràng, chiến lược xây dựng kiến trúc cụ thể, có kế hoạch scale rõ ràng | N35: Phần chi phí còn chung chung, chưa bóc tách chi tiết | O35: Nếu có 1000 người vào 1 lúc mà hệ thống bị lag thì phải làm sao | Q35: Best Enterprise Logic | R35: =IF(A35="","",F35+G35+H35+I35+J35+L35) -> 71 | S35: =IFERROR(__xludf.dummyfunction("""COMPUTED_VALUE"""),"NHÓM 1") -> NHÓM 1 | T35: =IFERROR(__xludf.dummyfunction("""COMPUTED_VALUE"""),"NHÓM 5") -> NHÓM 5 | U35: =IFERROR(__xludf.dummyfunction("IF(B35="""","""",""Zone ""&IFERROR(VALUE(REGEXEXTRACT(TRIM(B35),""\d+"")),REGEXEXTRACT(TRIM(B35),""\d+"")))"),"Zone 4") -> Zone 4
A36: 46134.681 | B36: Zone 2 | C36: Nhóm 11 | D36: Nhóm 9 | E36: EduPlusAI - Nền tảng Hỏi đáp nội bộ chuyên sâu trường học | F36: 12 | G36: 12 | H36: 8 | I36: 9 | J36: 6 | L36: 3 | M36: tập trung vào 1 phần chuyên sâu cụ thể của AI trong hệ thống trường học - cost giảm | N36: cải thiện cost - cần nguồn số liệu thực tế | O36: tại sao không dùng rulebase mà dùng các mô hình LLM | R36: =IF(A36="","",F36+G36+H36+I36+J36+L36) -> 50 | S36: =IFERROR(__xludf.dummyfunction("""COMPUTED_VALUE"""),"NHÓM 3") -> NHÓM 3 | T36: =IFERROR(__xludf.dummyfunction("""COMPUTED_VALUE"""),"NHÓM 5") -> NHÓM 5 | U36: =IFERROR(__xludf.dummyfunction("IF(B36="""","""",""Zone ""&IFERROR(VALUE(REGEXEXTRACT(TRIM(B36),""\d+"")),REGEXEXTRACT(TRIM(B36),""\d+"")))"),"Zone 2") -> Zone 2
A37: 46134.682 | B37: Zone 4 | C37: Nhóm 22 | D37: Nhóm 19 | E37: Vinschool one ai assistant | F37: 15 | G37: 20 | H37: 20 | I37: 15 | J37: 10 | L37: 5 | M37: MVP bao quát tốt | N37: Áp dụng rule base trc AI | O37: Nhóm tính áp dụng rule base như nào | Q37: Best Enterprise Logic, Best Cost Thinking, Best Reliability Mindset, Best Track Recommendation, Best Critical Feedback | R37: =IF(A37="","",F37+G37+H37+I37+J37+L37) -> 85 | S37: =IFERROR(__xludf.dummyfunction("""COMPUTED_VALUE"""),"NHÓM 1") -> NHÓM 1 | T37: =IFERROR(__xludf.dummyfunction("""COMPUTED_VALUE"""),"NHÓM 4") -> NHÓM 4 | U37: =IFERROR(__xludf.dummyfunction("IF(B37="""","""",""Zone ""&IFERROR(VALUE(REGEXEXTRACT(TRIM(B37),""\d+"")),REGEXEXTRACT(TRIM(B37),""\d+"")))"),"Zone 4") -> Zone 4
A38: 46134.682 | B38: 4 | C38: 21 | D38: 19 | E38: vinschool one ai assistant | F38: 15 | G38: 20 | H38: 20 | I38: 15 | J38: 10 | L38: 5 | M38: đã xog mvp, quá nhanh! | N38: áp dụng rule based để tiết kiệm hơn | O38: nếu tăng người dùng lên 10000 users, hướng giải quyết | R38: =IF(A38="","",F38+G38+H38+I38+J38+L38) -> 85 | S38: =IFERROR(__xludf.dummyfunction("""COMPUTED_VALUE"""),"NHÓM 1") -> NHÓM 1 | T38: =IFERROR(__xludf.dummyfunction("""COMPUTED_VALUE"""),"NHÓM 3") -> NHÓM 3 | U38: =IFERROR(__xludf.dummyfunction("IF(B38="""","""",""Zone ""&IFERROR(VALUE(REGEXEXTRACT(TRIM(B38),""\d+"")),REGEXEXTRACT(TRIM(B38),""\d+"")))"),"Zone 4") -> Zone 4
A39: 46134.682 | B39: 4 | C39: 20 | D39: 19 | E39: Vinschool One "Smart Hub" | F39: 15 | G39: 20 | H39: 16 | I39: 12 | J39: 10 | L39: 5 | M39: Team đã có mvp, giao diện mobile nhìn đẹp mắt | N39: Team đang overloaded với AI với tất cả mọi vấn đề, cần các logic fixed rule hoặc sử dụng LLM Router để tối ưu chi phí | O39: Bạn nghĩ nghiệp vụ nào có thể đủ và không quá phức tạp để áp dụng rule base logic? | Q39: Best Reliability Mindset | R39: =IF(A39="","",F39+G39+H39+I39+J39+L39) -> 78 | S39: =IFERROR(__xludf.dummyfunction("""COMPUTED_VALUE"""),"NHÓM 1") -> NHÓM 1 | T39: =IFERROR(__xludf.dummyfunction("""COMPUTED_VALUE"""),"NHÓM 2") -> NHÓM 2 | U39: =IFERROR(__xludf.dummyfunction("IF(B39="""","""",""Zone ""&IFERROR(VALUE(REGEXEXTRACT(TRIM(B39),""\d+"")),REGEXEXTRACT(TRIM(B39),""\d+"")))"),"Zone 4") -> Zone 4
A40: 46134.683 | B40: Zone 4 | C40: Nhóm 34 | D40: Nhóm 23 | E40: Chatbot sale Vinfast | F40: 15 | G40: 20 | H40: 20 | I40: 15 | J40: 10 | L40: 5 | M40: 3 chiến lược rõ ràng, có % tiết kiệm | N40: Cần cải thiện slide trực quan hơn | O40: Human escalation khi confidence thấp thì workflow cụ thể ? Làm sao tránh phiền sale quá nhiều | Q40: Best Cost Thinking | R40: =IF(A40="","",F40+G40+H40+I40+J40+L40) -> 85 | S40: =IFERROR(__xludf.dummyfunction("""COMPUTED_VALUE"""),"NHÓM 5") -> NHÓM 5 | T40: =IFERROR(__xludf.dummyfunction("""COMPUTED_VALUE"""),"NHÓM 4") -> NHÓM 4 | U40: =IFERROR(__xludf.dummyfunction("IF(B40="""","""",""Zone ""&IFERROR(VALUE(REGEXEXTRACT(TRIM(B40),""\d+"")),REGEXEXTRACT(TRIM(B40),""\d+"")))"),"Zone 4") -> Zone 4
...

Sheet Ketqua
A1: Ten_nhom | B1: Zone | C1: So_phieu | D1: Diem_TB | E1: Bonus | F1: Diem_cuoi | G1: Xep_hang | I1: Zone | J1: Doi_dan_dau | K1: Diem_cao_nhat
A2: =IFERROR(__xludf.dummyfunction("IFERROR(SORT(UNIQUE(FILTER(#REF!,#REF!<>""""))),)"),"") | B2: {=IF(A2="","",IFERROR(INDEX('Form Responses 1'!U:U,MATCH(A2,#REF!,0)),"Chưa có"))} | C2: =IF(A2="","",COUNTIF(#REF!,A2)) | D2: =IF(A2="","",COUNTIF(#REF!,A2)) | E2: =IF(A2="","",0) | F2: =IF(A2="","",ROUND(D2+E2,1)) | G2: =IF(F2="","",RANK(F2,$F$2:$F$50,0)) | I2: =IFERROR(__xludf.dummyfunction("IFERROR(SORT(UNIQUE(FILTER('Form Responses 1'!U2:U1057,'Form Responses 1'!U2:U1057<>""""))),)"),"Zone 1") -> Zone 1 | J2: =IF(I2="","",IFERROR(INDEX($A$2:$A$50,MATCH(_xludf.maxifs($D$2:$D$50,$B$2:$B$50,I2),$D$2:$D$50,0)),"Chưa có phiếu")) -> Chưa có phiếu | K2: =IF(I2="","",IFERROR(_xludf.maxifs($D$2:$D$50,$B$2:$B$50,I2),0)) -> 0
B3: {=IF(A3="","",IFERROR(INDEX('Form Responses 1'!U:U,MATCH(A3,#REF!,0)),"Chưa có"))} | C3: =IF(A3="","",COUNTIF(#REF!,A3)) | D3: =IF(A3="","",COUNTIF(#REF!,A3)) | E3: =IF(A3="","",0) | F3: =IF(A3="","",ROUND(D3+E3,1)) | G3: =IF(F3="","",RANK(F3,$F$2:$F$50,0)) | I3: =IFERROR(__xludf.dummyfunction("""COMPUTED_VALUE"""),"Zone 2") -> Zone 2 | J3: =IF(I3="","",IFERROR(INDEX($A$2:$A$50,MATCH(_xludf.maxifs($D$2:$D$50,$B$2:$B$50,I3),$D$2:$D$50,0)),"Chưa có phiếu")) -> Chưa có phiếu | K3: =IF(I3="","",IFERROR(_xludf.maxifs($D$2:$D$50,$B$2:$B$50,I3),0)) -> 0
B4: {=IF(A4="","",IFERROR(INDEX('Form Responses 1'!U:U,MATCH(A4,#REF!,0)),"Chưa có"))} | C4: =IF(A4="","",COUNTIF(#REF!,A4)) | D4: =IF(A4="","",COUNTIF(#REF!,A4)) | E4: =IF(A4="","",0) | F4: =IF(A4="","",ROUND(D4+E4,1)) | G4: =IF(F4="","",RANK(F4,$F$2:$F$50,0)) | I4: =IFERROR(__xludf.dummyfunction("""COMPUTED_VALUE"""),"Zone 3") -> Zone 3 | J4: =IF(I4="","",IFERROR(INDEX($A$2:$A$50,MATCH(_xludf.maxifs($D$2:$D$50,$B$2:$B$50,I4),$D$2:$D$50,0)),"Chưa có phiếu")) -> Chưa có phiếu | K4: =IF(I4="","",IFERROR(_xludf.maxifs($D$2:$D$50,$B$2:$B$50,I4),0)) -> 0
B5: {=IF(A5="","",IFERROR(INDEX('Form Responses 1'!U:U,MATCH(A5,#REF!,0)),"Chưa có"))} | C5: =IF(A5="","",COUNTIF(#REF!,A5)) | D5: =IF(A5="","",COUNTIF(#REF!,A5)) | E5: =IF(A5="","",0) | F5: =IF(A5="","",ROUND(D5+E5,1)) | G5: =IF(F5="","",RANK(F5,$F$2:$F$50,0)) | I5: =IFERROR(__xludf.dummyfunction("""COMPUTED_VALUE"""),"Zone 4") -> Zone 4 | J5: =IF(I5="","",IFERROR(INDEX($A$2:$A$50,MATCH(_xludf.maxifs($D$2:$D$50,$B$2:$B$50,I5),$D$2:$D$50,0)),"Chưa có phiếu")) -> Chưa có phiếu | K5: =IF(I5="","",IFERROR(_xludf.maxifs($D$2:$D$50,$B$2:$B$50,I5),0)) -> 0
B6: {=IF(A6="","",IFERROR(INDEX('Form Responses 1'!U:U,MATCH(A6,#REF!,0)),"Chưa có"))} | C6: =IF(A6="","",COUNTIF(#REF!,A6)) | D6: =IF(A6="","",COUNTIF(#REF!,A6)) | E6: =IF(A6="","",0) | F6: =IF(A6="","",ROUND(D6+E6,1)) | G6: =IF(F6="","",RANK(F6,$F$2:$F$50,0)) | I6: =IFERROR(__xludf.dummyfunction("""COMPUTED_VALUE"""),"Zone 5") -> Zone 5 | J6: =IF(I6="","",IFERROR(INDEX($A$2:$A$50,MATCH(_xludf.maxifs($D$2:$D$50,$B$2:$B$50,I6),$D$2:$D$50,0)),"Chưa có phiếu")) -> Chưa có phiếu | K6: =IF(I6="","",IFERROR(_xludf.maxifs($D$2:$D$50,$B$2:$B$50,I6),0)) -> 0
B7: {=IF(A7="","",IFERROR(INDEX('Form Responses 1'!U:U,MATCH(A7,#REF!,0)),"Chưa có"))} | C7: =IF(A7="","",COUNTIF(#REF!,A7)) | D7: =IF(A7="","",COUNTIF(#REF!,A7)) | E7: =IF(A7="","",0) | F7: =IF(A7="","",ROUND(D7+E7,1)) | G7: =IF(F7="","",RANK(F7,$F$2:$F$50,0)) | I7: =IFERROR(__xludf.dummyfunction("""COMPUTED_VALUE"""),"Zone 6") -> Zone 6 | J7: =IF(I7="","",IFERROR(INDEX($A$2:$A$50,MATCH(_xludf.maxifs($D$2:$D$50,$B$2:$B$50,I7),$D$2:$D$50,0)),"Chưa có phiếu")) -> Chưa có phiếu | K7: =IF(I7="","",IFERROR(_xludf.maxifs($D$2:$D$50,$B$2:$B$50,I7),0)) -> 0
B8: {=IF(A8="","",IFERROR(INDEX('Form Responses 1'!U:U,MATCH(A8,#REF!,0)),"Chưa có"))} | C8: =IF(A8="","",COUNTIF(#REF!,A8)) | D8: =IF(A8="","",COUNTIF(#REF!,A8)) | E8: =IF(A8="","",0) | F8: =IF(A8="","",ROUND(D8+E8,1)) | G8: =IF(F8="","",RANK(F8,$F$2:$F$50,0)) | J8: =IF(I8="","",IFERROR(INDEX($A$2:$A$50,MATCH(_xludf.maxifs($D$2:$D$50,$B$2:$B$50,I8),$D$2:$D$50,0)),"Chưa có phiếu")) | K8: =IF(I8="","",IFERROR(_xludf.maxifs($D$2:$D$50,$B$2:$B$50,I8),0))
B9: {=IF(A9="","",IFERROR(INDEX('Form Responses 1'!U:U,MATCH(A9,#REF!,0)),"Chưa có"))} | C9: =IF(A9="","",COUNTIF(#REF!,A9)) | D9: =IF(A9="","",COUNTIF(#REF!,A9)) | E9: =IF(A9="","",0) | F9: =IF(A9="","",ROUND(D9+E9,1)) | G9: =IF(F9="","",RANK(F9,$F$2:$F$50,0))
B10: {=IF(A10="","",IFERROR(INDEX('Form Responses 1'!U:U,MATCH(A10,#REF!,0)),"Chưa có"))} | C10: =IF(A10="","",COUNTIF(#REF!,A10)) | D10: =IF(A10="","",COUNTIF(#REF!,A10)) | E10: =IF(A10="","",0) | F10: =IF(A10="","",ROUND(D10+E10,1)) | G10: =IF(F10="","",RANK(F10,$F$2:$F$50,0))
B11: {=IF(A11="","",IFERROR(INDEX('Form Responses 1'!U:U,MATCH(A11,#REF!,0)),"Chưa có"))} | C11: =IF(A11="","",COUNTIF(#REF!,A11)) | D11: =IF(A11="","",COUNTIF(#REF!,A11)) | E11: =IF(A11="","",0) | F11: =IF(A11="","",ROUND(D11+E11,1)) | G11: =IF(F11="","",RANK(F11,$F$2:$F$50,0))
B12: {=IF(A12="","",IFERROR(INDEX('Form Responses 1'!U:U,MATCH(A12,#REF!,0)),"Chưa có"))} | C12: =IF(A12="","",COUNTIF(#REF!,A12)) | D12: =IF(A12="","",COUNTIF(#REF!,A12)) | E12: =IF(A12="","",0) | F12: =IF(A12="","",ROUND(D12+E12,1)) | G12: =IF(F12="","",RANK(F12,$F$2:$F$50,0))
B13: {=IF(A13="","",IFERROR(INDEX('Form Responses 1'!U:U,MATCH(A13,#REF!,0)),"Chưa có"))} | C13: =IF(A13="","",COUNTIF(#REF!,A13)) | D13: =IF(A13="","",COUNTIF(#REF!,A13)) | E13: =IF(A13="","",0) | F13: =IF(A13="","",ROUND(D13+E13,1)) | G13: =IF(F13="","",RANK(F13,$F$2:$F$50,0))
B14: {=IF(A14="","",IFERROR(INDEX('Form Responses 1'!U:U,MATCH(A14,#REF!,0)),"Chưa có"))} | C14: =IF(A14="","",COUNTIF(#REF!,A14)) | D14: =IF(A14="","",COUNTIF(#REF!,A14)) | E14: =IF(A14="","",0) | F14: =IF(A14="","",ROUND(D14+E14,1)) | G14: =IF(F14="","",RANK(F14,$F$2:$F$50,0))
B15: {=IF(A15="","",IFERROR(INDEX('Form Responses 1'!U:U,MATCH(A15,#REF!,0)),"Chưa có"))} | C15: =IF(A15="","",COUNTIF(#REF!,A15)) | D15: =IF(A15="","",COUNTIF(#REF!,A15)) | E15: =IF(A15="","",0) | F15: =IF(A15="","",ROUND(D15+E15,1)) | G15: =IF(F15="","",RANK(F15,$F$2:$F$50,0))
B16: {=IF(A16="","",IFERROR(INDEX('Form Responses 1'!U:U,MATCH(A16,#REF!,0)),"Chưa có"))} | C16: =IF(A16="","",COUNTIF(#REF!,A16)) | D16: =IF(A16="","",COUNTIF(#REF!,A16)) | E16: =IF(A16="","",0) | F16: =IF(A16="","",ROUND(D16+E16,1)) | G16: =IF(F16="","",RANK(F16,$F$2:$F$50,0))
B17: {=IF(A17="","",IFERROR(INDEX('Form Responses 1'!U:U,MATCH(A17,#REF!,0)),"Chưa có"))} | C17: =IF(A17="","",COUNTIF(#REF!,A17)) | D17: =IF(A17="","",COUNTIF(#REF!,A17)) | E17: =IF(A17="","",0) | F17: =IF(A17="","",ROUND(D17+E17,1)) | G17: =IF(F17="","",RANK(F17,$F$2:$F$50,0))
B18: {=IF(A18="","",IFERROR(INDEX('Form Responses 1'!U:U,MATCH(A18,#REF!,0)),"Chưa có"))} | C18: =IF(A18="","",COUNTIF(#REF!,A18)) | D18: =IF(A18="","",COUNTIF(#REF!,A18)) | E18: =IF(A18="","",0) | F18: =IF(A18="","",ROUND(D18+E18,1)) | G18: =IF(F18="","",RANK(F18,$F$2:$F$50,0))
B19: {=IF(A19="","",IFERROR(INDEX('Form Responses 1'!U:U,MATCH(A19,#REF!,0)),"Chưa có"))} | C19: =IF(A19="","",COUNTIF(#REF!,A19)) | D19: =IF(A19="","",COUNTIF(#REF!,A19)) | E19: =IF(A19="","",0) | F19: =IF(A19="","",ROUND(D19+E19,1)) | G19: =IF(F19="","",RANK(F19,$F$2:$F$50,0))
B20: {=IF(A20="","",IFERROR(INDEX('Form Responses 1'!U:U,MATCH(A20,#REF!,0)),"Chưa có"))} | C20: =IF(A20="","",COUNTIF(#REF!,A20)) | D20: =IF(A20="","",COUNTIF(#REF!,A20)) | E20: =IF(A20="","",0) | F20: =IF(A20="","",ROUND(D20+E20,1)) | G20: =IF(F20="","",RANK(F20,$F$2:$F$50,0))
... B41: {=IF(A41="","",IFERROR(INDEX('Form Responses 1'!U:U,MATCH(A41,#REF!,0)),"Chưa có"))} | C41: =IF(A41="","",COUNTIF(#REF!,A41)) | D41: =IF(A41="","",COUNTIF(#REF!,A41)) | E41: =IF(A41="","",0) | F41: =IF(A41="","",ROUND(D41+E41,1)) | G41: =IF(F41="","",RANK(F41,$F$2:$F$50,0))
